Workbook

Sheet 到院前預警比例
A1: 本局6/1-6/30到院前預警案件執行率
B2: 有送醫有預警案件 | C2: 有送醫案件 | D2: 到院前預警率
A3: 第一大隊 | B3: =SUM(B4:B15) -> 2686 | C3: =SUM(C4:C15) -> 2866 | D3: =AVERAGE(D4:D15) -> 0.93531611
A4: =_xlfn.XLOOKUP(排序!E3, 排序!A:A, 排序!A:A, "") -> 桃園分隊 | B4: =_xlfn.XLOOKUP(排序!E3, 排序!A:A, 排序!B:B, "") -> 266 | C4: =_xlfn.XLOOKUP(排序!E3, 排序!A:A, 排序!C:C, "") -> 279 | D4: =_xlfn.XLOOKUP(排序!E3, 排序!A:A, 排序!D:D, "") -> 0.95340502
A5: =_xlfn.XLOOKUP(排序!E4, 排序!A:A, 排序!A:A, "") -> 中路分隊 | B5: =_xlfn.XLOOKUP(排序!E4, 排序!A:A, 排序!B:B, "") -> 179 | C5: =_xlfn.XLOOKUP(排序!E4, 排序!A:A, 排序!C:C, "") -> 198 | D5: =_xlfn.XLOOKUP(排序!E4, 排序!A:A, 排序!D:D, "") -> 0.9040404
A6: =_xlfn.XLOOKUP(排序!E5, 排序!A:A, 排序!A:A, "") -> 大林分隊 | B6: =_xlfn.XLOOKUP(排序!E5, 排序!A:A, 排序!B:B, "") -> 265 | C6: =_xlfn.XLOOKUP(排序!E5, 排序!A:A, 排序!C:C, "") -> 277 | D6: =_xlfn.XLOOKUP(排序!E5, 排序!A:A, 排序!D:D, "") -> 0.9566787
A7: =_xlfn.XLOOKUP(排序!E6, 排序!A:A, 排序!A:A, "") -> 三民分隊 | B7: =_xlfn.XLOOKUP(排序!E6, 排序!A:A, 排序!B:B, "") -> 381 | C7: =_xlfn.XLOOKUP(排序!E6, 排序!A:A, 排序!C:C, "") -> 410 | D7: =_xlfn.XLOOKUP(排序!E6, 排序!A:A, 排序!D:D, "") -> 0.92926829
A8: =_xlfn.XLOOKUP(排序!E7, 排序!A:A, 排序!A:A, "") -> 大有分隊 | B8: =_xlfn.XLOOKUP(排序!E7, 排序!A:A, 排序!B:B, "") -> 194 | C8: =_xlfn.XLOOKUP(排序!E7, 排序!A:A, 排序!C:C, "") -> 225 | D8: =_xlfn.XLOOKUP(排序!E7, 排序!A:A, 排序!D:D, "") -> 0.86222222
A9: =_xlfn.XLOOKUP(排序!E8, 排序!A:A, 排序!A:A, "") -> 埔子分隊 | B9: =_xlfn.XLOOKUP(排序!E8, 排序!A:A, 排序!B:B, "") -> 209 | C9: =_xlfn.XLOOKUP(排序!E8, 排序!A:A, 排序!C:C, "") -> 221 | D9: =_xlfn.XLOOKUP(排序!E8, 排序!A:A, 排序!D:D, "") -> 0.94570136
A10: =_xlfn.XLOOKUP(排序!E9, 排序!A:A, 排序!A:A, "") -> 八德分隊 | B10: =_xlfn.XLOOKUP(排序!E9, 排序!A:A, 排序!B:B, "") -> 211 | C10: =_xlfn.XLOOKUP(排序!E9, 排序!A:A, 排序!C:C, "") -> 218 | D10: =_xlfn.XLOOKUP(排序!E9, 排序!A:A, 排序!D:D, "") -> 0.96788991
A11: =_xlfn.XLOOKUP(排序!E10, 排序!A:A, 排序!A:A, "") -> 大湳分隊 | B11: =_xlfn.XLOOKUP(排序!E10, 排序!A:A, 排序!B:B, "") -> 248 | C11: =_xlfn.XLOOKUP(排序!E10, 排序!A:A, 排序!C:C, "") -> 266 | D11: =_xlfn.XLOOKUP(排序!E10, 排序!A:A, 排序!D:D, "") -> 0.93233083
A12: =_xlfn.XLOOKUP(排序!E11, 排序!A:A, 排序!A:A, "") -> 茄苳分隊 | B12: =_xlfn.XLOOKUP(排序!E11, 排序!A:A, 排序!B:B, "") -> 180 | C12: =_xlfn.XLOOKUP(排序!E11, 排序!A:A, 排序!C:C, "") -> 193 | D12: =_xlfn.XLOOKUP(排序!E11, 排序!A:A, 排序!D:D, "") -> 0.93264249
A13: =_xlfn.XLOOKUP(排序!E12, 排序!A:A, 排序!A:A, "") -> 龜山分隊 | B13: =_xlfn.XLOOKUP(排序!E12, 排序!A:A, 排序!B:B, "") -> 261 | C13: =_xlfn.XLOOKUP(排序!E12, 排序!A:A, 排序!C:C, "") -> 268 | D13: =_xlfn.XLOOKUP(排序!E12, 排序!A:A, 排序!D:D, "") -> 0.9738806
A14: =_xlfn.XLOOKUP(排序!E13, 排序!A:A, 排序!A:A, "") -> 坪頂分隊 | B14: =_xlfn.XLOOKUP(排序!E13, 排序!A:A, 排序!B:B, "") -> 222 | C14: =_xlfn.XLOOKUP(排序!E13, 排序!A:A, 排序!C:C, "") -> 235 | D14: =_xlfn.XLOOKUP(排序!E13, 排序!A:A, 排序!D:D, "") -> 0.94468085
A15: =_xlfn.XLOOKUP(排序!E14, 排序!A:A, 排序!A:A, "") -> 迴龍分隊 | B15: =_xlfn.XLOOKUP(排序!E14, 排序!A:A, 排序!B:B, "") -> 70 | C15: =_xlfn.XLOOKUP(排序!E14, 排序!A:A, 排序!C:C, "") -> 76 | D15: =_xlfn.XLOOKUP(排序!E14, 排序!A:A, 排序!D:D, "") -> 0.92105263
A16: 第二大隊 | B16: =SUM(B17:B28) -> 2452 | C16: =SUM(C17:C28) -> 2553 | D16: =AVERAGE(D17:D28) -> 0.95404344
A17: =_xlfn.XLOOKUP(排序!E15, 排序!A:A, 排序!A:A, "") -> 中壢分隊 | B17: =_xlfn.XLOOKUP(排序!E15, 排序!A:A, 排序!B:B, "") -> 359 | C17: =_xlfn.XLOOKUP(排序!E15, 排序!A:A, 排序!C:C, "") -> 369 | D17: =_xlfn.XLOOKUP(排序!E15, 排序!A:A, 排序!D:D, "") -> 0.97289973
A18: =_xlfn.XLOOKUP(排序!E16, 排序!A:A, 排序!A:A, "") -> 興國分隊 | B18: =_xlfn.XLOOKUP(排序!E16, 排序!A:A, 排序!B:B, "") -> 357 | C18: =_xlfn.XLOOKUP(排序!E16, 排序!A:A, 排序!C:C, "") -> 372 | D18: =_xlfn.XLOOKUP(排序!E16, 排序!A:A, 排序!D:D, "") -> 0.95967742
A19: =_xlfn.XLOOKUP(排序!E17, 排序!A:A, 排序!A:A, "") -> 華勛分隊 | B19: =_xlfn.XLOOKUP(排序!E17, 排序!A:A, 排序!B:B, "") -> 303 | C19: =_xlfn.XLOOKUP(排序!E17, 排序!A:A, 排序!C:C, "") -> 312 | D19: =_xlfn.XLOOKUP(排序!E17, 排序!A:A, 排序!D:D, "") -> 0.97115385
A20: =_xlfn.XLOOKUP(排序!E18, 排序!A:A, 排序!A:A, "") -> 內壢分隊 | B20: =_xlfn.XLOOKUP(排序!E18, 排序!A:A, 排序!B:B, "") -> 270 | C20: =_xlfn.XLOOKUP(排序!E18, 排序!A:A, 排序!C:C, "") -> 299 | D20: =_xlfn.XLOOKUP(排序!E18, 排序!A:A, 排序!D:D, "") -> 0.90301003
A21: =_xlfn.XLOOKUP(排序!E19, 排序!A:A, 排序!A:A, "") -> 龍岡分隊 | B21: =_xlfn.XLOOKUP(排序!E19, 排序!A:A, 排序!B:B, "") -> 237 | C21: =_xlfn.XLOOKUP(排序!E19, 排序!A:A, 排序!C:C, "") -> 244 | D21: =_xlfn.XLOOKUP(排序!E19, 排序!A:A, 排序!D:D, "") -> 0.97131148
A22: =_xlfn.XLOOKUP(排序!E20, 排序!A:A, 排序!A:A, "") -> 青埔分隊 | B22: =_xlfn.XLOOKUP(排序!E20, 排序!A:A, 排序!B:B, "") -> 179 | C22: =_xlfn.XLOOKUP(排序!E20, 排序!A:A, 排序!C:C, "") -> 183 | D22: =_xlfn.XLOOKUP(排序!E20, 排序!A:A, 排序!D:D, "") -> 0.97814208
A23: =_xlfn.XLOOKUP(排序!E21, 排序!A:A, 排序!A:A, "") -> 楊梅分隊 | B23: =_xlfn.XLOOKUP(排序!E21, 排序!A:A, 排序!B:B, "") -> 218 | C23: =_xlfn.XLOOKUP(排序!E21, 排序!A:A, 排序!C:C, "") -> 220 | D23: =_xlfn.XLOOKUP(排序!E21, 排序!A:A, 排序!D:D, "") -> 0.99090909
A24: =_xlfn.XLOOKUP(排序!E22, 排序!A:A, 排序!A:A, "") -> 幼獅分隊 | B24: =_xlfn.XLOOKUP(排序!E22, 排序!A:A, 排序!B:B, "") -> 119 | C24: =_xlfn.XLOOKUP(排序!E22, 排序!A:A, 排序!C:C, "") -> 125 | D24: =_xlfn.XLOOKUP(排序!E22, 排序!A:A, 排序!D:D, "") -> 0.952
A25: =_xlfn.XLOOKUP(排序!E23, 排序!A:A, 排序!A:A, "") -> 埔心分隊 | B25: =_xlfn.XLOOKUP(排序!E23, 排序!A:A, 排序!B:B, "") -> 158 | C25: =_xlfn.XLOOKUP(排序!E23, 排序!A:A, 排序!C:C, "") -> 162 | D25: =_xlfn.XLOOKUP(排序!E23, 排序!A:A, 排序!D:D, "") -> 0.97530864
A26: =_xlfn.XLOOKUP(排序!E24, 排序!A:A, 排序!A:A, "") -> 富岡分隊 | B26: =_xlfn.XLOOKUP(排序!E24, 排序!A:A, 排序!B:B, "") -> 103 | C26: =_xlfn.XLOOKUP(排序!E24, 排序!A:A, 排序!C:C, "") -> 106 | D26: =_xlfn.XLOOKUP(排序!E24, 排序!A:A, 排序!D:D, "") -> 0.97169811
A27: =_xlfn.XLOOKUP(排序!E25, 排序!A:A, 排序!A:A, "") -> 新屋分隊 | B27: =_xlfn.XLOOKUP(排序!E25, 排序!A:A, 排序!B:B, "") -> 105 | C27: =_xlfn.XLOOKUP(排序!E25, 排序!A:A, 排序!C:C, "") -> 108 | D27: =_xlfn.XLOOKUP(排序!E25, 排序!A:A, 排序!D:D, "") -> 0.97222222
A28: =_xlfn.XLOOKUP(排序!E26, 排序!A:A, 排序!A:A, "") -> 永安分隊 | B28: =_xlfn.XLOOKUP(排序!E26, 排序!A:A, 排序!B:B, "") -> 44 | C28: =_xlfn.XLOOKUP(排序!E26, 排序!A:A, 排序!C:C, "") -> 53 | D28: =_xlfn.XLOOKUP(排序!E26, 排序!A:A, 排序!D:D, "") -> 0.83018868
A29: 第三大隊 | B29: =SUM(B30:B37) -> 1010 | C29: =SUM(C30:C37) -> 1062 | D29: =AVERAGE(D30:D37) -> 0.94944053
A30: =_xlfn.XLOOKUP(排序!E27, 排序!A:A, 排序!A:A, "") -> 蘆竹分隊 | B30: =_xlfn.XLOOKUP(排序!E27, 排序!A:A, 排序!B:B, "") -> 247 | C30: =_xlfn.XLOOKUP(排序!E27, 排序!A:A, 排序!C:C, "") -> 255 | D30: =_xlfn.XLOOKUP(排序!E27, 排序!A:A, 排序!D:D, "") -> 0.96862745
A31: =_xlfn.XLOOKUP(排序!E28, 排序!A:A, 排序!A:A, "") -> 山腳分隊 | B31: =_xlfn.XLOOKUP(排序!E28, 排序!A:A, 排序!B:B, "") -> 107 | C31: =_xlfn.XLOOKUP(排序!E28, 排序!A:A, 排序!C:C, "") -> 119 | D31: =_xlfn.XLOOKUP(排序!E28, 排序!A:A, 排序!D:D, "") -> 0.89915966
A32: =_xlfn.XLOOKUP(排序!E29, 排序!A:A, 排序!A:A, "") -> 大竹分隊 | B32: =_xlfn.XLOOKUP(排序!E29, 排序!A:A, 排序!B:B, "") -> 157 | C32: =_xlfn.XLOOKUP(排序!E29, 排序!A:A, 排序!C:C, "") -> 165 | D32: =_xlfn.XLOOKUP(排序!E29, 排序!A:A, 排序!D:D, "") -> 0.95151515
A33: =_xlfn.XLOOKUP(排序!E30, 排序!A:A, 排序!A:A, "") -> 大園分隊 | B33: =_xlfn.XLOOKUP(排序!E30, 排序!A:A, 排序!B:B, "") -> 170 | C33: =_xlfn.XLOOKUP(排序!E30, 排序!A:A, 排序!C:C, "") -> 180 | D33: =_xlfn.XLOOKUP(排序!E30, 排序!A:A, 排序!D:D, "") -> 0.94444444
A34: =_xlfn.XLOOKUP(排序!E31, 排序!A:A, 排序!A:A, "") -> 竹圍分隊 | B34: =_xlfn.XLOOKUP(排序!E31, 排序!A:A, 排序!B:B, "") -> 78 | C34: =_xlfn.XLOOKUP(排序!E31, 排序!A:A, 排序!C:C, "") -> 80 | D34: =_xlfn.XLOOKUP(排序!E31, 排序!A:A, 排序!D:D, "") -> 0.975
A35: =_xlfn.XLOOKUP(排序!E32, 排序!A:A, 排序!A:A, "") -> 觀音分隊 | B35: =_xlfn.XLOOKUP(排序!E32, 排序!A:A, 排序!B:B, "") -> 64 | C35: =_xlfn.XLOOKUP(排序!E32, 排序!A:A, 排序!C:C, "") -> 69 | D35: =_xlfn.XLOOKUP(排序!E32, 排序!A:A, 排序!D:D, "") -> 0.92753623
A36: =_xlfn.XLOOKUP(排序!E33, 排序!A:A, 排序!A:A, "") -> 新坡分隊 | B36: =_xlfn.XLOOKUP(排序!E33, 排序!A:A, 排序!B:B, "") -> 90 | C36: =_xlfn.XLOOKUP(排序!E33, 排序!A:A, 排序!C:C, "") -> 92 | D36: =_xlfn.XLOOKUP(排序!E33, 排序!A:A, 排序!D:D, "") -> 0.97826087
A37: =_xlfn.XLOOKUP(排序!E34, 排序!A:A, 排序!A:A, "") -> 草漯分隊 | B37: =_xlfn.XLOOKUP(排序!E34, 排序!A:A, 排序!B:B, "") -> 97 | C37: =_xlfn.XLOOKUP(排序!E34, 排序!A:A, 排序!C:C, "") -> 102 | D37: =_xlfn.XLOOKUP(排序!E34, 排序!A:A, 排序!D:D, "") -> 0.95098039
A38: 第四大隊 | B38: =SUM(B39:B47) -> 1176 | C38: =SUM(C39:C47) -> 1220 | D38: =AVERAGE(D39:D47) -> 0.95343024
A39: =_xlfn.XLOOKUP(排序!E35, 排序!A:A, 排序!A:A, "") -> 圳頂分隊 | B39: =_xlfn.XLOOKUP(排序!E35, 排序!A:A, 排序!B:B, "") -> 140 | C39: =_xlfn.XLOOKUP(排序!E35, 排序!A:A, 排序!C:C, "") -> 147 | D39: =_xlfn.XLOOKUP(排序!E35, 排序!A:A, 排序!D:D, "") -> 0.95238095
A40: =_xlfn.XLOOKUP(排序!E36, 排序!A:A, 排序!A:A, "") -> 大溪分隊 | B40: =_xlfn.XLOOKUP(排序!E36, 排序!A:A, 排序!B:B, "") -> 142 | C40: =_xlfn.XLOOKUP(排序!E36, 排序!A:A, 排序!C:C, "") -> 147 | D40: =_xlfn.XLOOKUP(排序!E36, 排序!A:A, 排序!D:D, "") -> 0.96598639
...

Sheet 排序
A1: 本局6/1-6/30到院前預警案件執行率
B2: 有送醫有預警案件 | C2: 有送醫案件 | D2: 到院前預警率
A3: 八德分隊 | B3: 211 | C3: 218 | D3: =B3/C3 -> 0.96788991 | E3: 桃園分隊
A4: 三民分隊 | B4: 381 | C4: 410 | D4: =B4/C4 -> 0.92926829 | E4: 中路分隊
A5: 大有分隊 | B5: 194 | C5: 225 | D5: =B5/C5 -> 0.86222222 | E5: 大林分隊
A6: 大竹分隊 | B6: 157 | C6: 165 | D6: =B6/C6 -> 0.95151515 | E6: 三民分隊
A7: 大林分隊 | B7: 265 | C7: 277 | D7: =B7/C7 -> 0.9566787 | E7: 大有分隊
A8: 大湳分隊 | B8: 248 | C8: 266 | D8: =B8/C8 -> 0.93233083 | E8: 埔子分隊
A9: 大園分隊 | B9: 170 | C9: 180 | D9: =B9/C9 -> 0.94444444 | E9: 八德分隊
A10: 大溪分隊 | B10: 142 | C10: 147 | D10: =B10/C10 -> 0.96598639 | E10: 大湳分隊
A11: 山峰分隊 | B11: 144 | C11: 149 | D11: =B11/C11 -> 0.96644295 | E11: 茄苳分隊
A12: 山腳分隊 | B12: 107 | C12: 119 | D12: =B12/C12 -> 0.89915966 | E12: 龜山分隊
A13: 中路分隊 | B13: 179 | C13: 198 | D13: =B13/C13 -> 0.9040404 | E13: 坪頂分隊
A14: 中壢分隊 | B14: 359 | C14: 369 | D14: =B14/C14 -> 0.97289973 | E14: 迴龍分隊
... A43: 觀音分隊 | B43: 64 | C43: 69 | D43: =B43/C43 -> 0.92753623 | E43: 巴陵分隊
